<?xml version="1.0"?><robot name="rob">
	<link name="0">
		<visual>
			<geometry>
				<cylinder length="0.6885731031801839" radius="0.5000066643785868"/>
			</geometry>
		</visual>
		<collision>
			<geometry>
				<cylinder length="0.6885731031801839" radius="0.5000066643785868"/>
			</geometry>
		</collision>
		<inertial>
			<mass value="0.5408184671904129"/>
			<inertia ixx="0.03" iyy="0.03" izz="0.03" ixy="0" ixz="0" iyx="0"/>
		</inertial>
	</link>
	<link name="11">
		<visual>
			<geometry>
				<cylinder length="0.6065321253163667" radius="0.7436696660218431"/>
			</geometry>
		</visual>
		<collision>
			<geometry>
				<cylinder length="0.6065321253163667" radius="0.7436696660218431"/>
			</geometry>
		</collision>
		<inertial>
			<mass value="1.0538136398121012"/>
			<inertia ixx="0.03" iyy="0.03" izz="0.03" ixy="0" ixz="0" iyx="0"/>
		</inertial>
	</link>
	<link name="12">
		<visual>
			<geometry>
				<cylinder length="0.6065321253163667" radius="0.7436696660218431"/>
			</geometry>
		</visual>
		<collision>
			<geometry>
				<cylinder length="0.6065321253163667" radius="0.7436696660218431"/>
			</geometry>
		</collision>
		<inertial>
			<mass value="1.0538136398121012"/>
			<inertia ixx="0.03" iyy="0.03" izz="0.03" ixy="0" ixz="0" iyx="0"/>
		</inertial>
	</link>
	<link name="13">
		<visual>
			<geometry>
				<cylinder length="0.6065321253163667" radius="0.7436696660218431"/>
			</geometry>
		</visual>
		<collision>
			<geometry>
				<cylinder length="0.6065321253163667" radius="0.7436696660218431"/>
			</geometry>
		</collision>
		<inertial>
			<mass value="1.0538136398121012"/>
			<inertia ixx="0.03" iyy="0.03" izz="0.03" ixy="0" ixz="0" iyx="0"/>
		</inertial>
	</link>
	<link name="24">
		<visual>
			<geometry>
				<cylinder length="0.7687676898727434" radius="0.37796450308297536"/>
			</geometry>
		</visual>
		<collision>
			<geometry>
				<cylinder length="0.7687676898727434" radius="0.37796450308297536"/>
			</geometry>
		</collision>
		<inertial>
			<mass value="0.3450221873082667"/>
			<inertia ixx="0.03" iyy="0.03" izz="0.03" ixy="0" ixz="0" iyx="0"/>
		</inertial>
	</link>
	<link name="25">
		<visual>
			<geometry>
				<cylinder length="0.7687676898727434" radius="0.37796450308297536"/>
			</geometry>
		</visual>
		<collision>
			<geometry>
				<cylinder length="0.7687676898727434" radius="0.37796450308297536"/>
			</geometry>
		</collision>
		<inertial>
			<mass value="0.3450221873082667"/>
			<inertia ixx="0.03" iyy="0.03" izz="0.03" ixy="0" ixz="0" iyx="0"/>
		</inertial>
	</link>
	<joint name="11_to_0" type="revolute">
		<parent link="0"/>
		<child link="11"/>
		<axis xyz="1 0 0"/>
		<limit effort="1" upper="-3.1415" lower="3.1415" velocity="1"/>
		<origin rpy="7.701361495133089 2.8256097181372475 5.943517696791341" xyz="0.9694306409044672 0.7731945385048201 0.9708492058975732"/>
	</joint>
	<joint name="12_to_0" type="revolute">
		<parent link="0"/>
		<child link="12"/>
		<axis xyz="1 0 0"/>
		<limit effort="1" upper="-3.1415" lower="3.1415" velocity="1"/>
		<origin rpy="11.552042242699633 2.8256097181372475 5.943517696791341" xyz="0.9694306409044672 0.7731945385048201 0.9708492058975732"/>
	</joint>
	<joint name="13_to_0" type="revolute">
		<parent link="0"/>
		<child link="13"/>
		<axis xyz="1 0 0"/>
		<limit effort="1" upper="-3.1415" lower="3.1415" velocity="1"/>
		<origin rpy="15.402722990266177 2.8256097181372475 5.943517696791341" xyz="0.9694306409044672 0.7731945385048201 0.9708492058975732"/>
	</joint>
	<joint name="24_to_0" type="revolute">
		<parent link="0"/>
		<child link="24"/>
		<axis xyz="1 0 0"/>
		<limit effort="1" upper="-3.1415" lower="3.1415" velocity="1"/>
		<origin rpy="24.708662815572957 3.5090137775559835 1.4983289205736268" xyz="0.33882226597321674 0.3665991098778886 0.8762041938381492"/>
	</joint>
	<joint name="25_to_0" type="revolute">
		<parent link="0"/>
		<child link="25"/>
		<axis xyz="1 0 0"/>
		<limit effort="1" upper="-3.1415" lower="3.1415" velocity="1"/>
		<origin rpy="29.65039537868755 3.5090137775559835 1.4983289205736268" xyz="0.33882226597321674 0.3665991098778886 0.8762041938381492"/>
	</joint>
</robot>
