<?xml version="1.0"?><robot name="pepe">
	<link name="0">
		<visual>
			<geometry>
				<cylinder length="0.9468658796365681" radius="0.8825467095629808"/>
			</geometry>
		</visual>
		<collision>
			<geometry>
				<cylinder length="0.9468658796365681" radius="0.8825467095629808"/>
			</geometry>
		</collision>
		<inertial>
			<mass value="2.316934411795562"/>
			<inertia ixx="0.03" iyy="0.03" izz="0.03" ixy="0" ixz="0" iyx="0"/>
		</inertial>
	</link>
	<link name="11">
		<visual>
			<geometry>
				<cylinder length="0.8655964524447954" radius="0.5938015460244012"/>
			</geometry>
		</visual>
		<collision>
			<geometry>
				<cylinder length="0.8655964524447954" radius="0.5938015460244012"/>
			</geometry>
		</collision>
		<inertial>
			<mass value="0.9588440740832148"/>
			<inertia ixx="0.03" iyy="0.03" izz="0.03" ixy="0" ixz="0" iyx="0"/>
		</inertial>
	</link>
	<link name="12">
		<visual>
			<geometry>
				<cylinder length="0.8655964524447954" radius="0.5938015460244012"/>
			</geometry>
		</visual>
		<collision>
			<geometry>
				<cylinder length="0.8655964524447954" radius="0.5938015460244012"/>
			</geometry>
		</collision>
		<inertial>
			<mass value="0.9588440740832148"/>
			<inertia ixx="0.03" iyy="0.03" izz="0.03" ixy="0" ixz="0" iyx="0"/>
		</inertial>
	</link>
	<link name="13">
		<visual>
			<geometry>
				<cylinder length="0.8655964524447954" radius="0.5938015460244012"/>
			</geometry>
		</visual>
		<collision>
			<geometry>
				<cylinder length="0.8655964524447954" radius="0.5938015460244012"/>
			</geometry>
		</collision>
		<inertial>
			<mass value="0.9588440740832148"/>
			<inertia ixx="0.03" iyy="0.03" izz="0.03" ixy="0" ixz="0" iyx="0"/>
		</inertial>
	</link>
	<link name="14">
		<visual>
			<geometry>
				<cylinder length="0.8655964524447954" radius="0.5938015460244012"/>
			</geometry>
		</visual>
		<collision>
			<geometry>
				<cylinder length="0.8655964524447954" radius="0.5938015460244012"/>
			</geometry>
		</collision>
		<inertial>
			<mass value="0.9588440740832148"/>
			<inertia ixx="0.03" iyy="0.03" izz="0.03" ixy="0" ixz="0" iyx="0"/>
		</inertial>
	</link>
	<link name="25">
		<visual>
			<geometry>
				<cylinder length="0.8086510718733262" radius="0.6601453835202641"/>
			</geometry>
		</visual>
		<collision>
			<geometry>
				<cylinder length="0.8086510718733262" radius="0.6601453835202641"/>
			</geometry>
		</collision>
		<inertial>
			<mass value="1.1071085897364297"/>
			<inertia ixx="0.03" iyy="0.03" izz="0.03" ixy="0" ixz="0" iyx="0"/>
		</inertial>
	</link>
	<joint name="11_to_0" type="revolute">
		<parent link="0"/>
		<child link="11"/>
		<axis xyz="0 1 0"/>
		<limit effort="1" upper="-3.1415" lower="3.1415" velocity="1"/>
		<origin rpy="10.6191540330083 3.9144489454725457 1.238321839973915" xyz="0.044554485920938136 0.023154976680399897 0.8884342370844734"/>
	</joint>
	<joint name="12_to_0" type="revolute">
		<parent link="0"/>
		<child link="12"/>
		<axis xyz="0 1 0"/>
		<limit effort="1" upper="-3.1415" lower="3.1415" velocity="1"/>
		<origin rpy="15.92873104951245 3.9144489454725457 1.238321839973915" xyz="0.044554485920938136 0.023154976680399897 0.8884342370844734"/>
	</joint>
	<joint name="13_to_0" type="revolute">
		<parent link="0"/>
		<child link="13"/>
		<axis xyz="0 1 0"/>
		<limit effort="1" upper="-3.1415" lower="3.1415" velocity="1"/>
		<origin rpy="21.2383080660166 3.9144489454725457 1.238321839973915" xyz="0.044554485920938136 0.023154976680399897 0.8884342370844734"/>
	</joint>
	<joint name="14_to_0" type="revolute">
		<parent link="0"/>
		<child link="14"/>
		<axis xyz="0 1 0"/>
		<limit effort="1" upper="-3.1415" lower="3.1415" velocity="1"/>
		<origin rpy="26.54788508252075 3.9144489454725457 1.238321839973915" xyz="0.044554485920938136 0.023154976680399897 0.8884342370844734"/>
	</joint>
	<joint name="25_to_0" type="revolute">
		<parent link="0"/>
		<child link="25"/>
		<axis xyz="0 1 0"/>
		<limit effort="1" upper="-3.1415" lower="3.1415" velocity="1"/>
		<origin rpy="28.381403145241013 1.0528244871783272 5.610370351102431" xyz="0.9850575657269619 0.9290763979916213 0.7419399626130487"/>
	</joint>
</robot>
