<?xml version="1.0"?>
<robot name="myfirst">
    <joint name="leg_link1" type="revolute">
        <parent link="base_link"/>
        <child link="sub_link1"/>
        <axis xyz="0 0 1"/>
        <limit effort="10" upper="0" lower="10" velocity="1"/>
        <origin rpy="1 0 0" xyz="0 -0.15 -0.35"/>
    </joint>  
    <joint name="leg_link2" type="revolute">
        <parent link="base_link"/>
        <child link="sub_link2"/>
        <axis xyz="0 0 1"/>
        <limit effort="10" upper="0" lower="10" velocity="1"/>
        <origin rpy="1 0 0" xyz="0 0.15 -0.35"/>
    </joint> 
    <joint name="arm_link1" type="revolute">
        <parent link="base_link"/>
        <child link="sub_link3"/>
        <axis xyz="0 0 1"/>
        <limit effort="10" upper="0" lower="10" velocity="1"/>
        <origin rpy="1 0 0" xyz="0 -0.25 0.05"/>
    </joint> 
    <joint name="arm_link2" type="revolute">
        <parent link="base_link"/>
        <child link="sub_link4"/>
        <axis xyz="0 0 1"/>
        <limit effort="10" upper="0" lower="10" velocity="1"/>
        <origin rpy="1 0 0" xyz="0 0.25 0.05"/>
    </joint>   
    <joint name="head_link" type="fixed">
        <parent link="base_link"/>
        <child link="sub_link5"/>
        <origin rpy="1 0 0" xyz="0.06 0 0.33"/>
    </joint>   
    <link name="sub_link1">
        <visual>
                <geometry>
                    <sphere radius="0.1"/>
                </geometry>
            </visual>
            <collision>
                <geometry>
                    <sphere radius="0.1"/>
                </geometry>
            </collision>
            <inertial>
                <mass value="0.1"/>
                    <inertia ixx="0.0003" iyy="0.0003" izz="0.0003" ixy="0" ixz="0" iyz="0"/>
            </inertial>
    </link>
    <link name="sub_link2">
        <visual>
                <geometry>
                    <sphere radius="0.1"/>
                </geometry>
            </visual>
            <collision>
                <geometry>
                    <sphere radius="0.1"/>
                </geometry>
            </collision>
            <inertial>
                <mass value="0.1"/>
                    <inertia ixx="0.0003" iyy="0.0003" izz="0.0003" ixy="0" ixz="0" iyz="0"/>
            </inertial>
    </link>
    <link name="sub_link3">
        <visual>
                <geometry>
                    <sphere radius="0.1"/>
                </geometry>
            </visual>
            <collision>
                <geometry>
                    <sphere radius="0.1"/>
                </geometry>
            </collision>
            <inertial>
                <mass value="0.1"/>
                    <inertia ixx="0.0003" iyy="0.0003" izz="0.0003" ixy="0" ixz="0" iyz="0"/>
            </inertial>
    </link>
    <link name="sub_link4">
        <visual>
                <geometry>
                    <sphere radius="0.1"/>
                </geometry>
            </visual>
            <collision>
                <geometry>
                    <sphere radius="0.1"/>
                </geometry>
            </collision>
            <inertial>
                <mass value="0.1"/>
                    <inertia ixx="0.0003" iyy="0.0003" izz="0.0003" ixy="0" ixz="0" iyz="0"/>
            </inertial>
    </link>
    <link name="sub_link5">
        <visual>
            <origin rpy ="0 1.5 0" xyz="0 0 0"/>
            <geometry>
                <cylinder radius="0.09" length="0.2"/>
            </geometry>
        </visual>
        <visual>
            <origin rpy ="0 0 0" xyz="0.1 0 0.01"/>
            <geometry>
                <sphere radius="0.091"/>
            </geometry>
        </visual>
        <collision>
            <geometry>
                <cylinder radius="0.09" length="0.2"/>
            </geometry>
        </collision>
        <collision>
            <geometry>
                <sphere radius="0.091"/>
            </geometry>
        </collision>
            <inertial>
                <mass value="0.1"/>
                    <inertia ixx="0.0003" iyy="0.0003" izz="0.0003" ixy="0" ixz="0" iyz="0"/>
            </inertial>
    </link>
    <link name="base_link">
        <visual>
            <geometry>
                <cylinder radius="0.1" length="0.4"/>
            </geometry>
        </visual>
        <collision>
            <geometry>
                <cylinder radius="0.1" length="0.4"/>
            </geometry>
        </collision>
        <inertial>
            <mass value="0.25"/>
                <inertia ixx="0.0003" iyy="0.0003" izz="0.0003" ixy="0" ixz="0" iyz="0"/>
        </inertial>

    </link>
    
</robot>